2014-01-06T16:53:28.573385+00:00 app[web.1]: Traceback (most recent call last):
2014-01-06T16:53:28.573385+00:00 app[web.1]:     response = self.full_dispatch_request()
2014-01-06T16:53:28.573385+00:00 app[web.1]:   File "/app/.heroku/python/lib/python2.7/site-packages/flask/app.py", line 1817, in wsgi_app
2014-01-06T16:53:28.573385+00:00 app[web.1]:     rv = self.handle_user_exception(e)
2014-01-06T16:53:28.573385+00:00 app[web.1]:   File "/app/.heroku/python/lib/python2.7/site-packages/flask/app.py", line 1477, in full_dispatch_request
2014-01-06T16:53:28.573385+00:00 app[web.1]:   File "/app/.heroku/python/lib/python2.7/site-packages/flask/app.py", line 1381, in handle_user_exception
2014-01-06T16:53:28.573385+00:00 app[web.1]:     rv = self.dispatch_request()
2014-01-06T16:53:28.573708+00:00 app[web.1]:   File "/app/.heroku/python/lib/python2.7/site-packages/flask/app.py", line 1461, in dispatch_request
2014-01-06T16:53:28.573708+00:00 app[web.1]:     return self.view_functions[rule.endpoint](**req.view_args)
2014-01-06T16:53:28.573708+00:00 app[web.1]:   File "/app/base.py", line 20, in check_login
2014-01-06T16:53:28.573708+00:00 app[web.1]:     return handler(*args, **kwargs)
2014-01-06T16:53:28.573708+00:00 app[web.1]:   File "/app/main.py", line 53, in markers
2014-01-06T16:53:28.573708+00:00 app[web.1]:     results = Marker.bounding_box_fetch(ne_lat, ne_lng, sw_lat, sw_lng)
2014-01-06T16:53:28.573708+00:00 app[web.1]:   File "/app/models.py", line 107, in bounding_box_fetch
2014-01-06T16:53:28.573708+00:00 app[web.1]:     logging.debug('got %d markers from db' % markers.count())
2014-01-06T16:53:28.573991+00:00 app[web.1]:   File "/app/.heroku/python/lib/python2.7/site-packages/sqlalchemy/orm/query.py", line 2337, in scalar
2014-01-06T16:53:28.573708+00:00 app[web.1]:   File "/app/.heroku/python/lib/python2.7/site-packages/sqlalchemy/orm/query.py", line 2531, in count
2014-01-06T16:53:28.573991+00:00 app[web.1]:   File "/app/.heroku/python/lib/python2.7/site-packages/sqlalchemy/orm/query.py", line 2306, in one
2014-01-06T16:53:28.573708+00:00 app[web.1]:     return self.from_self(col).scalar()
2014-01-06T16:53:28.573991+00:00 app[web.1]:     ret = self.one()
2014-01-06T16:53:28.573991+00:00 app[web.1]:   File "/app/.heroku/python/lib/python2.7/site-packages/sqlalchemy/orm/query.py", line 2349, in __iter__
2014-01-06T16:53:28.573991+00:00 app[web.1]:   File "/app/.heroku/python/lib/python2.7/site-packages/sqlalchemy/orm/query.py", line 2364, in _execute_and_instances
2014-01-06T16:53:28.573991+00:00 app[web.1]:     return self._execute_and_instances(context)
2014-01-06T16:53:28.573991+00:00 app[web.1]:     ret = list(self)
2014-01-06T16:53:28.573991+00:00 app[web.1]:     result = conn.execute(querycontext.statement, self._params)
2014-01-06T16:53:28.573991+00:00 app[web.1]:   File "/app/.heroku/python/lib/python2.7/site-packages/sqlalchemy/engine/base.py", line 662, in execute
2014-01-06T16:53:28.573991+00:00 app[web.1]:     params)
2014-01-06T16:53:28.574712+00:00 app[web.1]:   File "/app/.heroku/python/lib/python2.7/site-packages/sqlalchemy/engine/base.py", line 761, in _execute_clauseelement
2014-01-06T16:53:28.574712+00:00 app[web.1]:     compiled_sql, distilled_params
2014-01-06T16:53:28.574712+00:00 app[web.1]:   File "/app/.heroku/python/lib/python2.7/site-packages/sqlalchemy/engine/base.py", line 828, in _execute_context
2014-01-06T16:53:28.574712+00:00 app[web.1]:   File "/app/.heroku/python/lib/python2.7/site-packages/sqlalchemy/engine/base.py", line 1024, in _handle_dbapi_exception
2014-01-06T16:53:28.574712+00:00 app[web.1]:     exc_info
2014-01-06T16:53:28.574712+00:00 app[web.1]:     None, None)
2014-01-06T16:53:28.574712+00:00 app[web.1]:     conn = self._revalidate_connection()
2014-01-06T16:53:28.574990+00:00 app[web.1]:     "Can't reconnect until invalid "
2014-01-06T16:53:28.574990+00:00 app[web.1]: StatementError: Can't reconnect until invalid transaction is rolled back (original cause: InvalidRequestError: Can't reconnect until invalid transaction is rolled back) 'SELECT count(*) AS count_1 \nFROM (SELECT markers.id AS markers_id, markers.user AS markers_user, markers.title AS markers_title, markers.description AS markers_description, markers.type AS markers_type, markers.subtype AS markers_subtype, markers.created AS markers_created, markers.latitude AS markers_latitude, markers.longitude AS markers_longitude, markers.address AS markers_address \nFROM markers \nWHERE markers.longitude <= %s AND markers.longitude >= %s AND markers.latitude <= %s AND markers.latitude >= %s) AS anon_1' [immutabledict({})]
2014-01-06T16:53:28.574712+00:00 app[web.1]:   File "/app/.heroku/python/lib/python2.7/site-packages/sqlalchemy/util/compat.py", line 195, in raise_from_cause
2014-01-06T16:53:28.574712+00:00 app[web.1]:     reraise(type(exception), exception, tb=exc_tb)
2014-01-06T16:53:28.574712+00:00 app[web.1]:   File "/app/.heroku/python/lib/python2.7/site-packages/sqlalchemy/engine/base.py", line 822, in _execute_context
2014-01-06T16:53:28.574990+00:00 app[web.1]:   File "/app/.heroku/python/lib/python2.7/site-packages/sqlalchemy/engine/base.py", line 239, in _revalidate_connection
2014-01-06T16:53:28.585690+00:00 heroku[router]: at=info method=GET path=/markers?ne_lat=32.078597794655344&ne_lng=34.795599857286106&sw_lat=32.072479507615554&sw_lng=34.78199569316257&zoom=17 host=anyway.herokuapp.com fwd="81.218.124.50" dyno=web.1 connect=8ms service=18ms status=500 bytes=291
2014-01-06T16:52:27.368768+00:00 heroku[router]: at=info method=GET path=/markers?ne_lat=32.07728530657974&ne_lng=34.796656647637974&sw_lat=32.07575575124612&sw_lng=34.79325560660709&zoom=19 host=anyway.herokuapp.com fwd="81.218.124.50" dyno=web.1 connect=2ms service=146ms status=500 bytes=291
2014-01-06T16:52:32.111032+00:00 heroku[router]: at=info method=GET path=/markers?ne_lat=32.08156588001128&ne_lng=34.80229465098728&sw_lat=32.06932929377441&sw_lng=34.77508632274021&zoom=16 host=anyway.herokuapp.com fwd="81.218.124.50" dyno=web.1 connect=2ms service=63ms status=500 bytes=291
2014-01-06T16:51:00.661531+00:00 heroku[router]: at=info method=GET path=/markers?ne_lat=32.07276247605633&ne_lng=34.80043319793094&sw_lat=32.06728932468281&sw_lng=34.78845981688846&zoom=17 host=anyway.herokuapp.com fwd="81.218.124.50" dyno=web.1 connect=1ms service=37ms status=500 bytes=291
2014-01-06T16:54:02.739542+00:00 heroku[router]: at=info method=GET path=/ host=anyway.herokuapp.com fwd="81.218.124.50" dyno=web.1 connect=5ms service=123ms status=200 bytes=6316
2014-01-06T16:54:03.137129+00:00 heroku[router]: at=info method=GET path=/static/js/libs/underscore.js host=anyway.herokuapp.com fwd="81.218.124.50" dyno=web.1 connect=1ms service=6ms status=304 bytes=0
2014-01-06T16:54:03.304762+00:00 heroku[router]: at=info method=GET path=/static/js/markerdialog.js host=anyway.herokuapp.com fwd="81.218.124.50" dyno=web.1 connect=3ms service=15ms status=304 bytes=0
2014-01-06T16:54:03.322001+00:00 heroku[router]: at=info method=GET path=/static/js/marker.js host=anyway.herokuapp.com fwd="81.218.124.50" dyno=web.1 connect=1ms service=26ms status=304 bytes=0
2014-01-06T16:54:03.376132+00:00 heroku[router]: at=info method=GET path=/static/js/libs/bootstrap.js host=anyway.herokuapp.com fwd="81.218.124.50" dyno=web.1 connect=22ms service=22ms status=304 bytes=0
2014-01-06T16:54:05.310827+00:00 heroku[router]: at=info method=GET path=/static/js/app.js host=anyway.herokuapp.com fwd="81.218.124.50" dyno=web.1 connect=28ms service=7ms status=304 bytes=0
2014-01-06T16:54:06.307839+00:00 heroku[router]: at=info method=POST path=/login host=anyway.herokuapp.com fwd="81.218.124.50" dyno=web.1 connect=28ms service=14ms status=400 bytes=192
2014-01-06T16:54:09.277334+00:00 app[web.1]: DEBUG:root:getting markers
2014-01-06T16:54:09.279618+00:00 app[web.1]: DEBUG:root:got params
2014-01-06T16:54:09.279993+00:00 app[web.1]: 
2014-01-06T16:54:09.280215+00:00 app[web.1]: DEBUG:root:querying markers in bouding box
2014-01-06T16:54:09.302664+00:00 app[web.1]: ERROR:main:Exception on /markers [GET]
2014-01-06T16:54:09.302664+00:00 app[web.1]: Traceback (most recent call last):
2014-01-06T16:54:09.302664+00:00 app[web.1]:     response = self.full_dispatch_request()
2014-01-06T16:54:09.302664+00:00 app[web.1]:     rv = self.handle_user_exception(e)
2014-01-06T16:54:09.302664+00:00 app[web.1]:   File "/app/.heroku/python/lib/python2.7/site-packages/flask/app.py", line 1381, in handle_user_exception
2014-01-06T16:54:09.302664+00:00 app[web.1]:   File "/app/.heroku/python/lib/python2.7/site-packages/flask/app.py", line 1817, in wsgi_app
2014-01-06T16:54:09.302664+00:00 app[web.1]:     rv = self.dispatch_request()
2014-01-06T16:54:09.302664+00:00 app[web.1]:     reraise(exc_type, exc_value, tb)
2014-01-06T16:54:09.302664+00:00 app[web.1]:   File "/app/.heroku/python/lib/python2.7/site-packages/flask/app.py", line 1475, in full_dispatch_request
2014-01-06T16:54:09.302664+00:00 app[web.1]:   File "/app/.heroku/python/lib/python2.7/site-packages/flask/app.py", line 1477, in full_dispatch_request
2014-01-06T16:54:09.303205+00:00 app[web.1]:     params)
2014-01-06T16:54:09.302952+00:00 app[web.1]:   File "/app/.heroku/python/lib/python2.7/site-packages/flask/app.py", line 1461, in dispatch_request
2014-01-06T16:54:09.302952+00:00 app[web.1]:     return self.view_functions[rule.endpoint](**req.view_args)
2014-01-06T16:54:09.302952+00:00 app[web.1]:   File "/app/base.py", line 20, in check_login
2014-01-06T16:54:09.302952+00:00 app[web.1]:     return handler(*args, **kwargs)
2014-01-06T16:54:09.302952+00:00 app[web.1]:   File "/app/main.py", line 53, in markers
2014-01-06T16:54:09.302952+00:00 app[web.1]:     results = Marker.bounding_box_fetch(ne_lat, ne_lng, sw_lat, sw_lng)
2014-01-06T16:54:09.303205+00:00 app[web.1]:     return self._execute_and_instances(context)
2014-01-06T16:54:09.303205+00:00 app[web.1]:   File "/app/.heroku/python/lib/python2.7/site-packages/sqlalchemy/orm/query.py", line 2364, in _execute_and_instances
2014-01-06T16:54:09.302952+00:00 app[web.1]:   File "/app/models.py", line 107, in bounding_box_fetch
2014-01-06T16:54:09.302952+00:00 app[web.1]:     logging.debug('got %d markers from db' % markers.count())
2014-01-06T16:54:09.302952+00:00 app[web.1]:   File "/app/.heroku/python/lib/python2.7/site-packages/sqlalchemy/orm/query.py", line 2531, in count
2014-01-06T16:54:09.303205+00:00 app[web.1]:     result = conn.execute(querycontext.statement, self._params)
2014-01-06T16:54:09.303205+00:00 app[web.1]:   File "/app/.heroku/python/lib/python2.7/site-packages/sqlalchemy/engine/base.py", line 662, in execute
2014-01-06T16:54:09.302952+00:00 app[web.1]:     return self.from_self(col).scalar()
2014-01-06T16:54:09.303205+00:00 app[web.1]:   File "/app/.heroku/python/lib/python2.7/site-packages/sqlalchemy/orm/query.py", line 2337, in scalar
2014-01-06T16:54:09.303205+00:00 app[web.1]:     ret = self.one()
2014-01-06T16:54:09.303205+00:00 app[web.1]:   File "/app/.heroku/python/lib/python2.7/site-packages/sqlalchemy/orm/query.py", line 2306, in one
2014-01-06T16:54:09.303205+00:00 app[web.1]:     ret = list(self)
2014-01-06T16:54:09.303205+00:00 app[web.1]:   File "/app/.heroku/python/lib/python2.7/site-packages/sqlalchemy/orm/query.py", line 2349, in __iter__
2014-01-06T16:54:09.303705+00:00 app[web.1]:   File "/app/.heroku/python/lib/python2.7/site-packages/sqlalchemy/engine/base.py", line 761, in _execute_clauseelement
2014-01-06T16:54:09.303705+00:00 app[web.1]:     compiled_sql, distilled_params
2014-01-06T16:54:09.303705+00:00 app[web.1]:   File "/app/.heroku/python/lib/python2.7/site-packages/sqlalchemy/engine/base.py", line 828, in _execute_context
2014-01-06T16:54:09.303705+00:00 app[web.1]:     None, None)
2014-01-06T16:54:09.303705+00:00 app[web.1]:   File "/app/.heroku/python/lib/python2.7/site-packages/sqlalchemy/engine/base.py", line 1024, in _handle_dbapi_exception
2014-01-06T16:54:09.303705+00:00 app[web.1]:     exc_info
2014-01-06T16:54:09.303705+00:00 app[web.1]:   File "/app/.heroku/python/lib/python2.7/site-packages/sqlalchemy/util/compat.py", line 195, in raise_from_cause
2014-01-06T16:54:09.303705+00:00 app[web.1]:     reraise(type(exception), exception, tb=exc_tb)
2014-01-06T16:54:09.303705+00:00 app[web.1]:   File "/app/.heroku/python/lib/python2.7/site-packages/sqlalchemy/engine/base.py", line 822, in _execute_context
2014-01-06T16:54:09.303705+00:00 app[web.1]:     conn = self._revalidate_connection()
2014-01-06T16:54:09.303887+00:00 app[web.1]:   File "/app/.heroku/python/lib/python2.7/site-packages/sqlalchemy/engine/base.py", line 239, in _revalidate_connection
2014-01-06T16:54:09.303887+00:00 app[web.1]:     "Can't reconnect until invalid "
2014-01-06T16:54:09.303887+00:00 app[web.1]: StatementError: Can't reconnect until invalid transaction is rolled back (original cause: InvalidRequestError: Can't reconnect until invalid transaction is rolled back) 'SELECT count(*) AS count_1 \nFROM (SELECT markers.id AS markers_id, markers.user AS markers_user, markers.title AS markers_title, markers.description AS markers_description, markers.type AS markers_type, markers.subtype AS markers_subtype, markers.created AS markers_created, markers.latitude AS markers_latitude, markers.longitude AS markers_longitude, markers.address AS markers_address \nFROM markers \nWHERE markers.longitude <= %s AND markers.longitude >= %s AND markers.latitude <= %s AND markers.latitude >= %s) AS anon_1' [immutabledict({})]
2014-01-06T16:54:03.133137+00:00 heroku[router]: at=info method=GET path=/static/js/libs/jquery-1.8.2.min.js host=anyway.herokuapp.com fwd="81.218.124.50" dyno=web.1 connect=1ms service=8ms status=304 bytes=0
2014-01-06T16:54:09.312474+00:00 heroku[router]: at=info method=GET path=/markers?ne_lat=32.07184290409366&ne_lng=34.80049805745546&sw_lat=32.067988055280736&sw_lng=34.78773074254457&zoom=17 host=anyway.herokuapp.com fwd="81.218.124.50" dyno=web.1 connect=8ms service=36ms status=500 bytes=291
2014-01-06T16:54:03.347659+00:00 heroku[router]: at=info method=GET path=/static/js/sidebar.js host=anyway.herokuapp.com fwd="81.218.124.50" dyno=web.1 connect=5ms service=50ms status=304 bytes=0
